Workbook

Sheet Netlist
A1: VESTA v1 ground station netlist (schematic VESTA-v1-SCH-01, rev 1.0)
A2: Generated from the Altium export Sch_VESTA-v1.NET (Oct 29, 2026). One row per component pin, grouped by the drawn blocks of the single sheet Sch_VESTA-v1.SchDoc. Passive pins (R, C) are listed too. Orange = power net · Grey = GND or NC (not connected). If the schematic changes, re-export the .NET and regenerate.
A3: Schematic block | B3: Designator | C3: Pin | D3: Pin name | E3: Net | F3: Note
A4: ESP32-DevKitC V4 | B4: MCU1 | C4: 1 | D4: 3V3 | E4: VCC_3V3
A5: ESP32-DevKitC V4 | B5: MCU1 | C5: 2 | D5: EN | E5: NC | F5: Spare
A6: ESP32-DevKitC V4 | B6: MCU1 | C6: 3 | D6: SENSOR_VP (GPIO36) | E6: NC | F6: Spare
A7: ESP32-DevKitC V4 | B7: MCU1 | C7: 4 | D7: SENSOR_VN (GPIO39) | E7: SD_MISO_EXT | F7: Input-only. Ext module's own MISO
A8: ESP32-DevKitC V4 | B8: MCU1 | C8: 5 | D8: IO34 | E8: GPS_PPS | F8: Input-only
A9: ESP32-DevKitC V4 | B9: MCU1 | C9: 6 | D9: IO35 | E9: FIX_GPS | F9: Input-only
A10: ESP32-DevKitC V4 | B10: MCU1 | C10: 7 | D10: IO32 | E10: RFM95W_INT | F10: Interrupt
A11: ESP32-DevKitC V4 | B11: MCU1 | C11: 8 | D11: IO33 | E11: NC | F11: Spare
A12: ESP32-DevKitC V4 | B12: MCU1 | C12: 9 | D12: IO25 | E12: RFM95W_RESET
A13: ESP32-DevKitC V4 | B13: MCU1 | C13: 10 | D13: IO26 | E13: WS2812B_DATA | F13: RMT
A14: ESP32-DevKitC V4 | B14: MCU1 | C14: 11 | D14: IO27 | E14: BUZZER | F14: LEDC PWM tone
A15: ESP32-DevKitC V4 | B15: MCU1 | C15: 12 | D15: IO14 | E15: NC | F15: Spare
A16: ESP32-DevKitC V4 | B16: MCU1 | C16: 13 | D16: IO12 | E16: NC | F16: Do not connect — strapping (MTDI, 1.8 V flash if high)
A17: ESP32-DevKitC V4 | B17: MCU1 | C17: 14 | D17: GND1 | E17: GND
A18: ESP32-DevKitC V4 | B18: MCU1 | C18: 15 | D18: IO13 | E18: NC | F18: Spare
A19: ESP32-DevKitC V4 | B19: MCU1 | C19: 16 | D19: SD2 (GPIO9) | E19: NC | F19: Do not connect — internal SPI flash
A20: ESP32-DevKitC V4 | B20: MCU1 | C20: 17 | D20: SD3 (GPIO10) | E20: NC | F20: Do not connect — internal SPI flash
A21: ESP32-DevKitC V4 | B21: MCU1 | C21: 18 | D21: CMD (GPIO11) | E21: NC | F21: Do not connect — internal SPI flash
A22: ESP32-DevKitC V4 | B22: MCU1 | C22: 19 | D22: EXT_5V | E22: VCC_5V
A23: ESP32-DevKitC V4 | B23: MCU1 | C23: 20 | D23: CLK (GPIO6) | E23: NC | F23: Do not connect — internal SPI flash
A24: ESP32-DevKitC V4 | B24: MCU1 | C24: 21 | D24: SD0 (GPIO7) | E24: NC | F24: Do not connect — internal SPI flash
A25: ESP32-DevKitC V4 | B25: MCU1 | C25: 22 | D25: SD1 (GPIO8) | E25: NC | F25: Do not connect — internal SPI flash
A26: ESP32-DevKitC V4 | B26: MCU1 | C26: 23 | D26: IO15 | E26: NC | F26: Do not connect — strapping (MTDO)
A27: ESP32-DevKitC V4 | B27: MCU1 | C27: 24 | D27: IO2 | E27: NC | F27: Do not connect — strapping
A28: ESP32-DevKitC V4 | B28: MCU1 | C28: 25 | D28: IO0 | E28: NC | F28: Do not connect — strapping / BOOT
A29: ESP32-DevKitC V4 | B29: MCU1 | C29: 26 | D29: IO4 | E29: SD_CS_EXT
A30: ESP32-DevKitC V4 | B30: MCU1 | C30: 27 | D30: IO16 | E30: GPS_UART_TX | F30: UART2 RX ← GPS TX
A31: ESP32-DevKitC V4 | B31: MCU1 | C31: 28 | D31: IO17 | E31: GPS_UART_RX | F31: UART2 TX → GPS RX
A32: ESP32-DevKitC V4 | B32: MCU1 | C32: 29 | D32: IO5 | E32: RFM95W_CS | F32: VSPI CS0 (native). Strapping pin: default high = CS idle (OK)
A33: ESP32-DevKitC V4 | B33: MCU1 | C33: 30 | D33: IO18 | E33: SNS_SPI_SCK | F33: VSPI CLK (native)
A34: ESP32-DevKitC V4 | B34: MCU1 | C34: 31 | D34: IO19 | E34: SNS_SPI_MISO | F34: VSPI MISO (native)
A35: ESP32-DevKitC V4 | B35: MCU1 | C35: 32 | D35: GND2 | E35: GND
A36: ESP32-DevKitC V4 | B36: MCU1 | C36: 33 | D36: IO21 | E36: SD_CS | F36: Pull-up R5
A37: ESP32-DevKitC V4 | B37: MCU1 | C37: 34 | D37: RXD0 (GPIO3) | E37: NC | F37: Do not connect — UART0 to CP2102 (USB)
A38: ESP32-DevKitC V4 | B38: MCU1 | C38: 35 | D38: TXD0 (GPIO1) | E38: NC | F38: Do not connect — UART0 to CP2102 (USB)
A39: ESP32-DevKitC V4 | B39: MCU1 | C39: 36 | D39: IO22 | E39: NC | F39: Spare
A40: ESP32-DevKitC V4 | B40: MCU1 | C40: 37 | D40: IO23 | E40: SNS_SPI_MOSI | F40: VSPI MOSI (native)
...

Sheet Net check
A1: Net check
A2: Every net except NC must connect at least 2 pins. 'Pins' counts the Netlist tab live; a single-pin net is flagged.
A3: Net | B3: Pins | C3: Check | D3: Type
A4: VCC_3V3 | B4: =COUNTIF(Netlist!$E$4:$E$147,A4) -> 24 | C4: =IF(A4="NC","—",IF(B4>=2,"OK","SINGLE PIN")) -> OK | D4: Power
A5: VCC_5V | B5: =COUNTIF(Netlist!$E$4:$E$147,A5) -> 3 | C5: =IF(A5="NC","—",IF(B5>=2,"OK","SINGLE PIN")) -> OK | D5: Power
A6: GND | B6: =COUNTIF(Netlist!$E$4:$E$147,A6) -> 34 | C6: =IF(A6="NC","—",IF(B6>=2,"OK","SINGLE PIN")) -> OK | D6: Ground
A7: BUZZER | B7: =COUNTIF(Netlist!$E$4:$E$147,A7) -> 3 | C7: =IF(A7="NC","—",IF(B7>=2,"OK","SINGLE PIN")) -> OK | D7: Signal
A8: DAT1 | B8: =COUNTIF(Netlist!$E$4:$E$147,A8) -> 2 | C8: =IF(A8="NC","—",IF(B8>=2,"OK","SINGLE PIN")) -> OK | D8: Signal
A9: DAT2 | B9: =COUNTIF(Netlist!$E$4:$E$147,A9) -> 2 | C9: =IF(A9="NC","—",IF(B9>=2,"OK","SINGLE PIN")) -> OK | D9: Signal
A10: FIX_GPS | B10: =COUNTIF(Netlist!$E$4:$E$147,A10) -> 2 | C10: =IF(A10="NC","—",IF(B10>=2,"OK","SINGLE PIN")) -> OK | D10: Signal
A11: GPS_PPS | B11: =COUNTIF(Netlist!$E$4:$E$147,A11) -> 2 | C11: =IF(A11="NC","—",IF(B11>=2,"OK","SINGLE PIN")) -> OK | D11: Signal
A12: GPS_UART_RX | B12: =COUNTIF(Netlist!$E$4:$E$147,A12) -> 2 | C12: =IF(A12="NC","—",IF(B12>=2,"OK","SINGLE PIN")) -> OK | D12: Signal
A13: GPS_UART_TX | B13: =COUNTIF(Netlist!$E$4:$E$147,A13) -> 2 | C13: =IF(A13="NC","—",IF(B13>=2,"OK","SINGLE PIN")) -> OK | D13: Signal
A14: NetD1_A | B14: =COUNTIF(Netlist!$E$4:$E$147,A14) -> 3 | C14: =IF(A14="NC","—",IF(B14>=2,"OK","SINGLE PIN")) -> OK | D14: Signal
A15: NetJ1-1 | B15: =COUNTIF(Netlist!$E$4:$E$147,A15) -> 2 | C15: =IF(A15="NC","—",IF(B15>=2,"OK","SINGLE PIN")) -> OK | D15: Signal
... A30: NC | B30: =COUNTIF(Netlist!$E$4:$E$147,A30) -> 27 | C30: =IF(A30="NC","—",IF(B30>=2,"OK","SINGLE PIN")) -> — | D30: Not connected
A32: Nets flagged | B32: =COUNTIF(C4:C30,"SINGLE PIN") -> 0
A33: Pins in netlist | B33: =COUNTA(Netlist!E4:E147) -> 144

Sheet GPIO map
A1: ESP32 (WROOM-32D) GPIO map
A2: From the MCU1 rows of the Netlist tab. Firmware defines in Firmware/VESTA_GS_v1/VESTA_GS_v1.ino use the same GPIOs.
A3: GPIO | B3: Header pin (symbol) | C3: Net | D3: Status | E3: Note
A4: 0 | B4: 25 (IO0) | C4: NC | D4: Do not connect | E4: Do not connect — strapping / BOOT
A5: 1 | B5: 35 (TXD0 (GPIO1)) | C5: NC | D5: Do not connect | E5: Do not connect — UART0 to CP2102 (USB)
A6: 2 | B6: 24 (IO2) | C6: NC | D6: Do not connect | E6: Do not connect — strapping
A7: 3 | B7: 34 (RXD0 (GPIO3)) | C7: NC | D7: Do not connect | E7: Do not connect — UART0 to CP2102 (USB)
A8: 4 | B8: 26 (IO4) | C8: SD_CS_EXT | D8: Used
A9: 5 | B9: 29 (IO5) | C9: RFM95W_CS | D9: Used | E9: VSPI CS0 (native). Strapping pin: default high = CS idle (OK)
A10: 6 | B10: 20 (CLK (GPIO6)) | C10: NC | D10: Do not connect | E10: Do not connect — internal SPI flash
A11: 7 | B11: 21 (SD0 (GPIO7)) | C11: NC | D11: Do not connect | E11: Do not connect — internal SPI flash
A12: 8 | B12: 22 (SD1 (GPIO8)) | C12: NC | D12: Do not connect | E12: Do not connect — internal SPI flash
A13: 9 | B13: 16 (SD2 (GPIO9)) | C13: NC | D13: Do not connect | E13: Do not connect — internal SPI flash
A14: 10 | B14: 17 (SD3 (GPIO10)) | C14: NC | D14: Do not connect | E14: Do not connect — internal SPI flash
A15: 11 | B15: 18 (CMD (GPIO11)) | C15: NC | D15: Do not connect | E15: Do not connect — internal SPI flash
A16: 12 | B16: 13 (IO12) | C16: NC | D16: Do not connect | E16: Do not connect — strapping (MTDI, 1.8 V flash if high)
A17: 13 | B17: 15 (IO13) | C17: NC | D17: Spare | E17: Spare
A18: 14 | B18: 12 (IO14) | C18: NC | D18: Spare | E18: Spare
A19: 15 | B19: 23 (IO15) | C19: NC | D19: Do not connect | E19: Do not connect — strapping (MTDO)
A20: 16 | B20: 27 (IO16) | C20: GPS_UART_TX | D20: Used | E20: UART2 RX ← GPS TX
... A26: 23 | B26: 37 (IO23) | C26: SNS_SPI_MOSI | D26: Used | E26: VSPI MOSI (native)
A27: 25 | B27: 9 (IO25) | C27: RFM95W_RESET | D27: Used
A28: 26 | B28: 10 (IO26) | C28: WS2812B_DATA | D28: Used | E28: RMT
A29: 27 | B29: 11 (IO27) | C29: BUZZER | D29: Used | E29: LEDC PWM tone
A30: 32 | B30: 7 (IO32) | C30: RFM95W_INT | D30: Used | E30: Interrupt
A31: 33 | B31: 8 (IO33) | C31: NC | D31: Spare | E31: Spare
A32: 34 | B32: 5 (IO34) | C32: GPS_PPS | D32: Used | E32: Input-only
A33: 35 | B33: 6 (IO35) | C33: FIX_GPS | D33: Used | E33: Input-only
A34: 36 | B34: 3 (SENSOR_VP (GPIO36)) | C34: NC | D34: Spare | E34: Spare
A35: 39 | B35: 4 (SENSOR_VN (GPIO39)) | C35: SD_MISO_EXT | D35: Used | E35: Input-only. Ext module's own MISO
